Workbook
Name Slicer_City: #N/A

Sheet ev_charging_network_usage_
A1: Session_ID | B1: City | C1: Station_Type | D1: Vehicle_Type | E1: Membership_Type | F1: Charging_Start | G1: Charging_End | H1: Charging_Duration_Minutes | I1: Energy_Consumed_kWh | J1: Price_per_kWh | K1: Revenue | L1: Payment_Mode | M1: Customer_Rating | N1: Energy Level | O1: Customer Satisfaction | P1: Chaging Time Category | Q1: Station Code | R1: Time | S1: Date
A2: EVS100000 | B2: Delhi | C2: Super Fast Charger | D2: 4W EV | E2: Non-Member | F2: 45109.467 | G2: 45109.524 | H2: 82 | I2: 2.01 | J2: 10 | K2: 20.1 | L2: Wallet | M2: 4 | N2: =IF(ev_charging_network_usage_!$I2<=10,"Low",IF(ev_charging_network_usage_!$I2<=30,"Medium","High")) -> Low | O2: =IF(M2<=2,"Low Satisfaction",IF(M2<=4,"Medium Satisfaction","High Satisfaction")) -> Medium Satisfaction | P2: =IF(ev_charging_network_usage_!$H2<30,"Short Charging",IF(ev_charging_network_usage_!$H2<=60,"Medium Charging","Long Charging")) -> Long Charging | Q2: =IF(C2="Fast Charger",1,IF(C2="Standard Charger",2,IF(C2="Super Fast Charger",3,""))) -> 3 | R2: =TIME(HOUR(F2),MINUTE(F2),SECOND(F2)) -> 0.46666667 | S2: =DATE(YEAR(F2),MONTH(F2),DAY(F2)) -> 45109
A3: EVS100001 | B3: Kolkata | C3: Fast Charger | D3: 3W EV | E3: Non-Member | F3: 45483.625 | G3: 45483.643 | H3: 26 | I3: 25 | J3: 8 | K3: 200 | L3: UPI | M3: 5 | N3: =IF(ev_charging_network_usage_!$I3<=10,"Low",IF(ev_charging_network_usage_!$I3<=30,"Medium","High")) -> Medium | O3: =IF(M3<=2,"Low Satisfaction",IF(M3<=4,"Medium Satisfaction","High Satisfaction")) -> High Satisfaction | P3: =IF(ev_charging_network_usage_!$H3<30,"Short Charging",IF(ev_charging_network_usage_!$H3<=60,"Medium Charging","Long Charging")) -> Short Charging | Q3: =IF(C3="Fast Charger",1,IF(C3="Standard Charger",2,IF(C3="Super Fast Charger",3,""))) -> 1 | R3: =TIME(HOUR(F3),MINUTE(F3),SECOND(F3)) -> 0.625 | S3: =DATE(YEAR(F3),MONTH(F3),DAY(F3)) -> 45483
A4: EVS100002 | B4: Kolkata | C4: Fast Charger | D4: 3W EV | E4: Non-Member | F4: 26-01-2024 18:20 | G4: 26-01-2024 20:11 | H4: 111 | I4: 41.74 | J4: 12 | K4: 500.88 | L4: Subscription | M4: 4 | N4: =IF(ev_charging_network_usage_!$I4<=10,"Low",IF(ev_charging_network_usage_!$I4<=30,"Medium","High")) -> High | O4: =IF(M4<=2,"Low Satisfaction",IF(M4<=4,"Medium Satisfaction","High Satisfaction")) -> Medium Satisfaction | P4: =IF(ev_charging_network_usage_!$H4<30,"Short Charging",IF(ev_charging_network_usage_!$H4<=60,"Medium Charging","Long Charging")) -> Long Charging | Q4: =IF(C4="Fast Charger",1,IF(C4="Standard Charger",2,IF(C4="Super Fast Charger",3,""))) -> 1 | R4: =TIME(HOUR(F4),MINUTE(F4),SECOND(F4)) -> 0.76388889 | S4: =DATE(YEAR(F4),MONTH(F4),DAY(F4)) -> 45317
A5: EVS100003 | B5: Hyderabad | C5: Standard Charger | D5: Electric Bus | E5: Non-Member | F5: 45208.436 | G5: 45208.463 | H5: 39 | I5: 33 | J5: 10 | K5: 330 | L5: Subscription | M5: 5 | N5: =IF(ev_charging_network_usage_!$I5<=10,"Low",IF(ev_charging_network_usage_!$I5<=30,"Medium","High")) -> High | O5: =IF(M5<=2,"Low Satisfaction",IF(M5<=4,"Medium Satisfaction","High Satisfaction")) -> High Satisfaction | P5: =IF(ev_charging_network_usage_!$H5<30,"Short Charging",IF(ev_charging_network_usage_!$H5<=60,"Medium Charging","Long Charging")) -> Medium Charging | Q5: =IF(C5="Fast Charger",1,IF(C5="Standard Charger",2,IF(C5="Super Fast Charger",3,""))) -> 2 | R5: =TIME(HOUR(F5),MINUTE(F5),SECOND(F5)) -> 0.43611111 | S5: =DATE(YEAR(F5),MONTH(F5),DAY(F5)) -> 45208
A6: EVS100004 | B6: Kolkata | C6: Fast Charger | D6: Electric Bus | E6: Non-Member | F6: 45024.987 | G6: 45054.059 | H6: 104 | I6: 13.49 | J6: 12 | K6: 161.88 | L6: Subscription | M6: 2 | N6: =IF(ev_charging_network_usage_!$I6<=10,"Low",IF(ev_charging_network_usage_!$I6<=30,"Medium","High")) -> Medium | O6: =IF(M6<=2,"Low Satisfaction",IF(M6<=4,"Medium Satisfaction","High Satisfaction")) -> Low Satisfaction | P6: =IF(ev_charging_network_usage_!$H6<30,"Short Charging",IF(ev_charging_network_usage_!$H6<=60,"Medium Charging","Long Charging")) -> Long Charging | Q6: =IF(C6="Fast Charger",1,IF(C6="Standard Charger",2,IF(C6="Super Fast Charger",3,""))) -> 1 | R6: =TIME(HOUR(F6),MINUTE(F6),SECOND(F6)) -> 0.98680556 | S6: =DATE(YEAR(F6),MONTH(F6),DAY(F6)) -> 45024
A7: EVS100005 | B7: Kolkata | C7: Fast Charger | D7: 2W EV | E7: Member | F7: 29-01-2024 07:22 | G7: 29-01-2024 08:29 | H7: 67 | I7: 52.83 | J7: 8 | K7: 422.64 | L7: Credit Card | M7: 5 | N7: =IF(ev_charging_network_usage_!$I7<=10,"Low",IF(ev_charging_network_usage_!$I7<=30,"Medium","High")) -> High | O7: =IF(M7<=2,"Low Satisfaction",IF(M7<=4,"Medium Satisfaction","High Satisfaction")) -> High Satisfaction | P7: =IF(ev_charging_network_usage_!$H7<30,"Short Charging",IF(ev_charging_network_usage_!$H7<=60,"Medium Charging","Long Charging")) -> Long Charging | Q7: =IF(C7="Fast Charger",1,IF(C7="Standard Charger",2,IF(C7="Super Fast Charger",3,""))) -> 1 | R7: =TIME(HOUR(F7),MINUTE(F7),SECOND(F7)) -> 0.30694444 | S7: =DATE(YEAR(F7),MONTH(F7),DAY(F7)) -> 45320 | V7: City | W7: Average Energy Consumption | X7: Average Charging duration | Z7: UNIQUE CITIES
A8: EVS100006 | B8: Delhi | C8: Standard Charger | D8: 2W EV | E8: Member | F8: 29-07-2023 08:24 | G8: 29-07-2023 08:47 | H8: 23 | I8: 17.84 | J8: 8 | K8: 142.72 | L8: Subscription | M8: 3 | N8: =IF(ev_charging_network_usage_!$I8<=10,"Low",IF(ev_charging_network_usage_!$I8<=30,"Medium","High")) -> Medium | O8: =IF(M8<=2,"Low Satisfaction",IF(M8<=4,"Medium Satisfaction","High Satisfaction")) -> Medium Satisfaction | P8: =IF(ev_charging_network_usage_!$H8<30,"Short Charging",IF(ev_charging_network_usage_!$H8<=60,"Medium Charging","Long Charging")) -> Short Charging | Q8: =IF(C8="Fast Charger",1,IF(C8="Standard Charger",2,IF(C8="Super Fast Charger",3,""))) -> 2 | R8: =TIME(HOUR(F8),MINUTE(F8),SECOND(F8)) -> 0.35 | S8: =DATE(YEAR(F8),MONTH(F8),DAY(F8)) -> 45136 | V8: City Delhi | W8: =AVERAGEIF(B:B,B2,I:I) -> 30.491427 | X8: =AVERAGEIF(B:B,B2,H:H) -> 64.018138 | Z8: {=_xlfn.UNIQUE(B:B)} -> City
A9: EVS100007 | B9: Ahmedabad | C9: Fast Charger | D9: 3W EV | E9: Non-Member | F9: 25-09-2024 08:30 | G9: 25-09-2024 09:51 | H9: 81 | I9: 26.42 | J9: 8 | K9: 211.36 | L9: Credit Card | M9: 2 | N9: =IF(ev_charging_network_usage_!$I9<=10,"Low",IF(ev_charging_network_usage_!$I9<=30,"Medium","High")) -> Medium | O9: =IF(M9<=2,"Low Satisfaction",IF(M9<=4,"Medium Satisfaction","High Satisfaction")) -> Low Satisfaction | P9: =IF(ev_charging_network_usage_!$H9<30,"Short Charging",IF(ev_charging_network_usage_!$H9<=60,"Medium Charging","Long Charging")) -> Long Charging | Q9: =IF(C9="Fast Charger",1,IF(C9="Standard Charger",2,IF(C9="Super Fast Charger",3,""))) -> 1 | R9: =TIME(HOUR(F9),MINUTE(F9),SECOND(F9)) -> 0.35416667 | S9: =DATE(YEAR(F9),MONTH(F9),DAY(F9)) -> 45560 | V9: City Banglore | W9: =AVERAGEIF(B:B,B13,I:I) -> 30.477665 | X9: =AVERAGEIF(B:B,B13,H:H) -> 64.96066 | Z9: Delhi
A10: EVS100008 | B10: Delhi | C10: Fast Charger | D10: 2W EV | E10: Member | F10: 45210.128 | G10: 45210.151 | H10: 34 | I10: 20.3 | J10: 12 | K10: 243.6 | L10: Wallet | M10: 5 | N10: =IF(ev_charging_network_usage_!$I10<=10,"Low",IF(ev_charging_network_usage_!$I10<=30,"Medium","High")) -> Medium | O10: =IF(M10<=2,"Low Satisfaction",IF(M10<=4,"Medium Satisfaction","High Satisfaction")) -> High Satisfaction | P10: =IF(ev_charging_network_usage_!$H10<30,"Short Charging",IF(ev_charging_network_usage_!$H10<=60,"Medium Charging","Long Charging")) -> Medium Charging | Q10: =IF(C10="Fast Charger",1,IF(C10="Standard Charger",2,IF(C10="Super Fast Charger",3,""))) -> 1 | R10: =TIME(HOUR(F10),MINUTE(F10),SECOND(F10)) -> 0.12777778 | S10: =DATE(YEAR(F10),MONTH(F10),DAY(F10)) -> 45210 | V10: City Ahmedabad | W10: =AVERAGEIF(B:B,B9,I:I) -> 30.429816 | X10: =AVERAGEIF(B:B,B9,H:H) -> 62.651961 | Z10: Kolkata
A11: EVS100009 | B11: Chennai | C11: Super Fast Charger | D11: Electric Bus | E11: Non-Member | F11: 27-01-2023 20:16 | G11: 27-01-2023 22:15 | H11: 119 | I11: 3.98 | J11: 10 | K11: 39.8 | L11: Credit Card | M11: 3 | N11: =IF(ev_charging_network_usage_!$I11<=10,"Low",IF(ev_charging_network_usage_!$I11<=30,"Medium","High")) -> Low | O11: =IF(M11<=2,"Low Satisfaction",IF(M11<=4,"Medium Satisfaction","High Satisfaction")) -> Medium Satisfaction | P11: =IF(ev_charging_network_usage_!$H11<30,"Short Charging",IF(ev_charging_network_usage_!$H11<=60,"Medium Charging","Long Charging")) -> Long Charging | Q11: =IF(C11="Fast Charger",1,IF(C11="Standard Charger",2,IF(C11="Super Fast Charger",3,""))) -> 3 | R11: =TIME(HOUR(F11),MINUTE(F11),SECOND(F11)) -> 0.84444444 | S11: =DATE(YEAR(F11),MONTH(F11),DAY(F11)) -> 44953 | V11: City Hyderabad | W11: =AVERAGEIF(B:B,B5,I:I) -> 31.818596 | X11: =AVERAGEIF(B:B,B5,H:H) -> 63.504843 | Z11: Hyderabad
A12: EVS100010 | B12: Chennai | C12: Fast Charger | D12: Electric Bus | E12: Non-Member | F12: 16-01-2023 00:04 | G12: 16-01-2023 00:39 | H12: 35 | I12: 18.27 | J12: 15 | K12: 274.05 | L12: Subscription | M12: 3 | N12: =IF(ev_charging_network_usage_!$I12<=10,"Low",IF(ev_charging_network_usage_!$I12<=30,"Medium","High")) -> Medium | O12: =IF(M12<=2,"Low Satisfaction",IF(M12<=4,"Medium Satisfaction","High Satisfaction")) -> Medium Satisfaction | P12: =IF(ev_charging_network_usage_!$H12<30,"Short Charging",IF(ev_charging_network_usage_!$H12<=60,"Medium Charging","Long Charging")) -> Medium Charging | Q12: =IF(C12="Fast Charger",1,IF(C12="Standard Charger",2,IF(C12="Super Fast Charger",3,""))) -> 1 | R12: =TIME(HOUR(F12),MINUTE(F12),SECOND(F12)) -> 0.0027777778 | S12: =DATE(YEAR(F12),MONTH(F12),DAY(F12)) -> 44942 | V12: City Chennai | W12: =AVERAGEIF(B:B,B11,I:I) -> 30.26599 | X12: =AVERAGEIF(B:B,B11,H:H) -> 64.364882 | Z12: Ahmedabad
A13: EVS100011 | B13: Bangalore | C13: Super Fast Charger | D13: 3W EV | E13: Member | F13: 27-10-2024 08:22 | G13: 27-10-2024 08:41 | H13: 19 | I13: 7.58 | J13: 15 | K13: 113.7 | L13: Credit Card | M13: 5 | N13: =IF(ev_charging_network_usage_!$I13<=10,"Low",IF(ev_charging_network_usage_!$I13<=30,"Medium","High")) -> Low | O13: =IF(M13<=2,"Low Satisfaction",IF(M13<=4,"Medium Satisfaction","High Satisfaction")) -> High Satisfaction | P13: =IF(ev_charging_network_usage_!$H13<30,"Short Charging",IF(ev_charging_network_usage_!$H13<=60,"Medium Charging","Long Charging")) -> Short Charging | Q13: =IF(C13="Fast Charger",1,IF(C13="Standard Charger",2,IF(C13="Super Fast Charger",3,""))) -> 3 | R13: =TIME(HOUR(F13),MINUTE(F13),SECOND(F13)) -> 0.34861111 | S13: =DATE(YEAR(F13),MONTH(F13),DAY(F13)) -> 45592 | V13: City Mumbai | W13: =AVERAGEIF(B:B,B22,I:I) -> 31.104659 | X13: =AVERAGEIF(B:B,B22,H:H) -> 63.280566 | Z13: Chennai
A14: EVS100012 | B14: Pune | C14: Super Fast Charger | D14: 2W EV | E14: Non-Member | F14: 45052.248 | G14: 45052.312 | H14: 93 | I14: 55.18 | J14: 12 | K14: 662.16 | L14: Credit Card | M14: 1 | N14: =IF(ev_charging_network_usage_!$I14<=10,"Low",IF(ev_charging_network_usage_!$I14<=30,"Medium","High")) -> High | O14: =IF(M14<=2,"Low Satisfaction",IF(M14<=4,"Medium Satisfaction","High Satisfaction")) -> Low Satisfaction | P14: =IF(ev_charging_network_usage_!$H14<30,"Short Charging",IF(ev_charging_network_usage_!$H14<=60,"Medium Charging","Long Charging")) -> Long Charging | Q14: =IF(C14="Fast Charger",1,IF(C14="Standard Charger",2,IF(C14="Super Fast Charger",3,""))) -> 3 | R14: =TIME(HOUR(F14),MINUTE(F14),SECOND(F14)) -> 0.24791667 | S14: =DATE(YEAR(F14),MONTH(F14),DAY(F14)) -> 45052 | V14: City Pune | W14: =AVERAGEIF(B:B,Table2[[#This Row],[City]],I:I) -> 31.42577 | X14: =AVERAGEIF(B:B,Table2[[#This Row],[City]],H:H) -> 65.718434 | Z14: Bangalore
A15: EVS100013 | B15: Hyderabad | C15: Standard Charger | D15: 2W EV | E15: Non-Member | F15: 23-02-2024 10:23 | G15: 23-02-2024 10:48 | H15: 25 | I15: 5.1 | J15: 15 | K15: 76.5 | L15: Subscription | M15: 2 | N15: =IF(ev_charging_network_usage_!$I15<=10,"Low",IF(ev_charging_network_usage_!$I15<=30,"Medium","High")) -> Low | O15: =IF(M15<=2,"Low Satisfaction",IF(M15<=4,"Medium Satisfaction","High Satisfaction")) -> Low Satisfaction | P15: =IF(ev_charging_network_usage_!$H15<30,"Short Charging",IF(ev_charging_network_usage_!$H15<=60,"Medium Charging","Long Charging")) -> Short Charging | Q15: =IF(C15="Fast Charger",1,IF(C15="Standard Charger",2,IF(C15="Super Fast Charger",3,""))) -> 2 | R15: =TIME(HOUR(F15),MINUTE(F15),SECOND(F15)) -> 0.43263889 | S15: =DATE(YEAR(F15),MONTH(F15),DAY(F15)) -> 45345 | Z15: Pune
A16: EVS100014 | B16: Delhi | C16: Standard Charger | D16: 4W EV | E16: Non-Member | F16: 44935.449 | G16: 44935.478 | H16: 42 | I16: 7.94 | J16: 8 | K16: 63.52 | L16: UPI | M16: 2 | N16: =IF(ev_charging_network_usage_!$I16<=10,"Low",IF(ev_charging_network_usage_!$I16<=30,"Medium","High")) -> Low | O16: =IF(M16<=2,"Low Satisfaction",IF(M16<=4,"Medium Satisfaction","High Satisfaction")) -> Low Satisfaction | P16: =IF(ev_charging_network_usage_!$H16<30,"Short Charging",IF(ev_charging_network_usage_!$H16<=60,"Medium Charging","Long Charging")) -> Medium Charging | Q16: =IF(C16="Fast Charger",1,IF(C16="Standard Charger",2,IF(C16="Super Fast Charger",3,""))) -> 2 | R16: =TIME(HOUR(F16),MINUTE(F16),SECOND(F16)) -> 0.44861111 | S16: =DATE(YEAR(F16),MONTH(F16),DAY(F16)) -> 44935 | Z16: Mumbai
A17: EVS100015 | B17: Chennai | C17: Standard Charger | D17: 4W EV | E17: Non-Member | F17: 45413.544 | G17: 45413.551 | H17: 10 | I17: 4.9 | J17: 15 | K17: 73.5 | L17: Subscription | M17: 5 | N17: =IF(ev_charging_network_usage_!$I17<=10,"Low",IF(ev_charging_network_usage_!$I17<=30,"Medium","High")) -> Low | O17: =IF(M17<=2,"Low Satisfaction",IF(M17<=4,"Medium Satisfaction","High Satisfaction")) -> High Satisfaction | P17: =IF(ev_charging_network_usage_!$H17<30,"Short Charging",IF(ev_charging_network_usage_!$H17<=60,"Medium Charging","Long Charging")) -> Short Charging | Q17: =IF(C17="Fast Charger",1,IF(C17="Standard Charger",2,IF(C17="Super Fast Charger",3,""))) -> 2 | R17: =TIME(HOUR(F17),MINUTE(F17),SECOND(F17)) -> 0.54375 | S17: =DATE(YEAR(F17),MONTH(F17),DAY(F17)) -> 45413 | Z17: 0
A18: EVS100016 | B18: Hyderabad | C18: Fast Charger | D18: 4W EV | E18: Non-Member | F18: 14-04-2024 06:02 | G18: 14-04-2024 07:28 | H18: 86 | I18: 3.73 | J18: 15 | K18: 55.95 | L18: UPI | M18: 4 | N18: =IF(ev_charging_network_usage_!$I18<=10,"Low",IF(ev_charging_network_usage_!$I18<=30,"Medium","High")) -> Low | O18: =IF(M18<=2,"Low Satisfaction",IF(M18<=4,"Medium Satisfaction","High Satisfaction")) -> Medium Satisfaction | P18: =IF(ev_charging_network_usage_!$H18<30,"Short Charging",IF(ev_charging_network_usage_!$H18<=60,"Medium Charging","Long Charging")) -> Long Charging | Q18: =IF(C18="Fast Charger",1,IF(C18="Standard Charger",2,IF(C18="Super Fast Charger",3,""))) -> 1 | R18: =TIME(HOUR(F18),MINUTE(F18),SECOND(F18)) -> 0.25138889 | S18: =DATE(YEAR(F18),MONTH(F18),DAY(F18)) -> 45396
A19: EVS100017 | B19: Kolkata | C19: Standard Charger | D19: 4W EV | E19: Non-Member | F19: 21-09-2023 13:08 | G19: 21-09-2023 14:33 | H19: 85 | I19: 10.08 | J19: 8 | K19: 80.64 | L19: UPI | M19: 5 | N19: =IF(ev_charging_network_usage_!$I19<=10,"Low",IF(ev_charging_network_usage_!$I19<=30,"Medium","High")) -> Medium | O19: =IF(M19<=2,"Low Satisfaction",IF(M19<=4,"Medium Satisfaction","High Satisfaction")) -> High Satisfaction | P19: =IF(ev_charging_network_usage_!$H19<30,"Short Charging",IF(ev_charging_network_usage_!$H19<=60,"Medium Charging","Long Charging")) -> Long Charging | Q19: =IF(C19="Fast Charger",1,IF(C19="Standard Charger",2,IF(C19="Super Fast Charger",3,""))) -> 2 | R19: =TIME(HOUR(F19),MINUTE(F19),SECOND(F19)) -> 0.54722222 | S19: =DATE(YEAR(F19),MONTH(F19),DAY(F19)) -> 45190
A20: EVS100018 | B20: Chennai | C20: Standard Charger | D20: 3W EV | E20: Member | F20: 26-06-2024 04:39 | G20: 26-06-2024 04:56 | H20: 17 | I20: 39.83 | J20: 8 | K20: 318.64 | L20: UPI | M20: 2 | N20: =IF(ev_charging_network_usage_!$I20<=10,"Low",IF(ev_charging_network_usage_!$I20<=30,"Medium","High")) -> High | O20: =IF(M20<=2,"Low Satisfaction",IF(M20<=4,"Medium Satisfaction","High Satisfaction")) -> Low Satisfaction | P20: =IF(ev_charging_network_usage_!$H20<30,"Short Charging",IF(ev_charging_network_usage_!$H20<=60,"Medium Charging","Long Charging")) -> Short Charging | Q20: =IF(C20="Fast Charger",1,IF(C20="Standard Charger",2,IF(C20="Super Fast Charger",3,""))) -> 2 | R20: =TIME(HOUR(F20),MINUTE(F20),SECOND(F20)) -> 0.19375 | S20: =DATE(YEAR(F20),MONTH(F20),DAY(F20)) -> 45469
A21: EVS100019 | B21: Pune | C21: Super Fast Charger | D21: 2W EV | E21: Member | F21: 23-05-2024 18:32 | G21: 23-05-2024 18:55 | H21: 23 | I21: 9.33 | J21: 10 | K21: 93.3 | L21: Subscription | M21: 5 | N21: =IF(ev_charging_network_usage_!$I21<=10,"Low",IF(ev_charging_network_usage_!$I21<=30,"Medium","High")) -> Low | O21: =IF(M21<=2,"Low Satisfaction",IF(M21<=4,"Medium Satisfaction","High Satisfaction")) -> High Satisfaction | P21: =IF(ev_charging_network_usage_!$H21<30,"Short Charging",IF(ev_charging_network_usage_!$H21<=60,"Medium Charging","Long Charging")) -> Short Charging | Q21: =IF(C21="Fast Charger",1,IF(C21="Standard Charger",2,IF(C21="Super Fast Charger",3,""))) -> 3 | R21: =TIME(HOUR(F21),MINUTE(F21),SECOND(F21)) -> 0.77222222 | S21: =DATE(YEAR(F21),MONTH(F21),DAY(F21)) -> 45435 | Z21: =Z21 -> 0
A22: EVS100020 | B22: Mumbai | C22: Fast Charger | D22: Electric Bus | E22: Non-Member | F22: 44963.436 | G22: 44963.457 | H22: 30 | I22: 22.68 | J22: 10 | K22: 226.8 | L22: Credit Card | M22: 2 | N22: =IF(ev_charging_network_usage_!$I22<=10,"Low",IF(ev_charging_network_usage_!$I22<=30,"Medium","High")) -> Medium | O22: =IF(M22<=2,"Low Satisfaction",IF(M22<=4,"Medium Satisfaction","High Satisfaction")) -> Low Satisfaction | P22: =IF(ev_charging_network_usage_!$H22<30,"Short Charging",IF(ev_charging_network_usage_!$H22<=60,"Medium Charging","Long Charging")) -> Medium Charging | Q22: =IF(C22="Fast Charger",1,IF(C22="Standard Charger",2,IF(C22="Super Fast Charger",3,""))) -> 1 | R22: =TIME(HOUR(F22),MINUTE(F22),SECOND(F22)) -> 0.43611111 | S22: =DATE(YEAR(F22),MONTH(F22),DAY(F22)) -> 44963
A23: EVS100021 | B23: Ahmedabad | C23: Super Fast Charger | D23: 2W EV | E23: Non-Member | F23: 29-08-2024 09:24 | G23: 29-08-2024 10:56 | H23: 92 | I23: 30.89 | J23: 8 | K23: 247.12 | L23: Credit Card | M23: 3 | N23: =IF(ev_charging_network_usage_!$I23<=10,"Low",IF(ev_charging_network_usage_!$I23<=30,"Medium","High")) -> High | O23: =IF(M23<=2,"Low Satisfaction",IF(M23<=4,"Medium Satisfaction","High Satisfaction")) -> Medium Satisfaction | P23: =IF(ev_charging_network_usage_!$H23<30,"Short Charging",IF(ev_charging_network_usage_!$H23<=60,"Medium Charging","Long Charging")) -> Long Charging | Q23: =IF(C23="Fast Charger",1,IF(C23="Standard Charger",2,IF(C23="Super Fast Charger",3,""))) -> 3 | R23: =TIME(HOUR(F23),MINUTE(F23),SECOND(F23)) -> 0.39166667 | S23: =DATE(YEAR(F23),MONTH(F23),DAY(F23)) -> 45533
A24: EVS100022 | B24: Kolkata | C24: Standard Charger | D24: 3W EV | E24: Member | F24: 45478.315 | G24: 45478.329 | H24: 20 | I24: 22.61 | J24: 15 | K24: 339.15 | L24: Subscription | M24: 2 | N24: =IF(ev_charging_network_usage_!$I24<=10,"Low",IF(ev_charging_network_usage_!$I24<=30,"Medium","High")) -> Medium | O24: =IF(M24<=2,"Low Satisfaction",IF(M24<=4,"Medium Satisfaction","High Satisfaction")) -> Low Satisfaction | P24: =IF(ev_charging_network_usage_!$H24<30,"Short Charging",IF(ev_charging_network_usage_!$H24<=60,"Medium Charging","Long Charging")) -> Short Charging | Q24: =IF(C24="Fast Charger",1,IF(C24="Standard Charger",2,IF(C24="Super Fast Charger",3,""))) -> 2 | R24: =TIME(HOUR(F24),MINUTE(F24),SECOND(F24)) -> 0.31527778 | S24: =DATE(YEAR(F24),MONTH(F24),DAY(F24)) -> 45478
A25: EVS100023 | B25: Hyderabad | C25: Standard Charger | D25: 2W EV | E25: Non-Member | F25: 15-04-2024 06:02 | G25: 15-04-2024 07:23 | H25: 81 | I25: 46.75 | J25: 8 | K25: 374 | L25: Subscription | M25: 2 | N25: =IF(ev_charging_network_usage_!$I25<=10,"Low",IF(ev_charging_network_usage_!$I25<=30,"Medium","High")) -> High | O25: =IF(M25<=2,"Low Satisfaction",IF(M25<=4,"Medium Satisfaction","High Satisfaction")) -> Low Satisfaction | P25: =IF(ev_charging_network_usage_!$H25<30,"Short Charging",IF(ev_charging_network_usage_!$H25<=60,"Medium Charging","Long Charging")) -> Long Charging | Q25: =IF(C25="Fast Charger",1,IF(C25="Standard Charger",2,IF(C25="Super Fast Charger",3,""))) -> 2 | R25: =TIME(HOUR(F25),MINUTE(F25),SECOND(F25)) -> 0.25138889 | S25: =DATE(YEAR(F25),MONTH(F25),DAY(F25)) -> 45397
A26: EVS100024 | B26: Delhi | C26: Fast Charger | D26: Electric Bus | E26: Member | F26: 20-06-2023 20:54 | G26: 20-06-2023 21:52 | H26: 58 | I26: 2.52 | J26: 15 | K26: 37.8 | L26: UPI | M26: 2 | N26: =IF(ev_charging_network_usage_!$I26<=10,"Low",IF(ev_charging_network_usage_!$I26<=30,"Medium","High")) -> Low | O26: =IF(M26<=2,"Low Satisfaction",IF(M26<=4,"Medium Satisfaction","High Satisfaction")) -> Low Satisfaction | P26: =IF(ev_charging_network_usage_!$H26<30,"Short Charging",IF(ev_charging_network_usage_!$H26<=60,"Medium Charging","Long Charging")) -> Medium Charging | Q26: =IF(C26="Fast Charger",1,IF(C26="Standard Charger",2,IF(C26="Super Fast Charger",3,""))) -> 1 | R26: =TIME(HOUR(F26),MINUTE(F26),SECOND(F26)) -> 0.87083333 | S26: =DATE(YEAR(F26),MONTH(F26),DAY(F26)) -> 45097
A27: EVS100025 | B27: Pune | C27: Standard Charger | D27: 4W EV | E27: Member | F27: 18-09-2024 01:53 | G27: 18-09-2024 03:27 | H27: 94 | I27: 29.11 | J27: 8 | K27: 232.88 | L27: Credit Card | M27: 1 | N27: =IF(ev_charging_network_usage_!$I27<=10,"Low",IF(ev_charging_network_usage_!$I27<=30,"Medium","High")) -> Medium | O27: =IF(M27<=2,"Low Satisfaction",IF(M27<=4,"Medium Satisfaction","High Satisfaction")) -> Low Satisfaction | P27: =IF(ev_charging_network_usage_!$H27<30,"Short Charging",IF(ev_charging_network_usage_!$H27<=60,"Medium Charging","Long Charging")) -> Long Charging | Q27: =IF(C27="Fast Charger",1,IF(C27="Standard Charger",2,IF(C27="Super Fast Charger",3,""))) -> 2 | R27: =TIME(HOUR(F27),MINUTE(F27),SECOND(F27)) -> 0.078472222 | S27: =DATE(YEAR(F27),MONTH(F27),DAY(F27)) -> 45553
A28: EVS100026 | B28: Chennai | C28: Super Fast Charger | D28: Electric Bus | E28: Non-Member | F28: 45567.314 | G28: 45567.378 | H28: 93 | I28: 9.95 | J28: 15 | K28: 149.25 | L28: Subscription | M28: 5 | N28: =IF(ev_charging_network_usage_!$I28<=10,"Low",IF(ev_charging_network_usage_!$I28<=30,"Medium","High")) -> Low | O28: =IF(M28<=2,"Low Satisfaction",IF(M28<=4,"Medium Satisfaction","High Satisfaction")) -> High Satisfaction | P28: =IF(ev_charging_network_usage_!$H28<30,"Short Charging",IF(ev_charging_network_usage_!$H28<=60,"Medium Charging","Long Charging")) -> Long Charging | Q28: =IF(C28="Fast Charger",1,IF(C28="Standard Charger",2,IF(C28="Super Fast Charger",3,""))) -> 3 | R28: =TIME(HOUR(F28),MINUTE(F28),SECOND(F28)) -> 0.31388889 | S28: =DATE(YEAR(F28),MONTH(F28),DAY(F28)) -> 45567
A29: EVS100027 | B29: Mumbai | C29: Standard Charger | D29: 4W EV | E29: Member | F29: 20-09-2024 11:06 | G29: 20-09-2024 12:33 | H29: 87 | I29: 31.48 | J29: 12 | K29: 377.76 | L29: Subscription | M29: 1 | N29: =IF(ev_charging_network_usage_!$I29<=10,"Low",IF(ev_charging_network_usage_!$I29<=30,"Medium","High")) -> High | O29: =IF(M29<=2,"Low Satisfaction",IF(M29<=4,"Medium Satisfaction","High Satisfaction")) -> Low Satisfaction | P29: =IF(ev_charging_network_usage_!$H29<30,"Short Charging",IF(ev_charging_network_usage_!$H29<=60,"Medium Charging","Long Charging")) -> Long Charging | Q29: =IF(C29="Fast Charger",1,IF(C29="Standard Charger",2,IF(C29="Super Fast Charger",3,""))) -> 2 | R29: =TIME(HOUR(F29),MINUTE(F29),SECOND(F29)) -> 0.4625 | S29: =DATE(YEAR(F29),MONTH(F29),DAY(F29)) -> 45555
A30: EVS100028 | B30: Delhi | C30: Super Fast Charger | D30: 2W EV | E30: Member | F30: 18-05-2023 02:07 | G30: 18-05-2023 03:10 | H30: 63 | I30: 3.15 | J30: 10 | K30: 31.5 | L30: Subscription | M30: 1 | N30: =IF(ev_charging_network_usage_!$I30<=10,"Low",IF(ev_charging_network_usage_!$I30<=30,"Medium","High")) -> Low | O30: =IF(M30<=2,"Low Satisfaction",IF(M30<=4,"Medium Satisfaction","High Satisfaction")) -> Low Satisfaction | P30: =IF(ev_charging_network_usage_!$H30<30,"Short Charging",IF(ev_charging_network_usage_!$H30<=60,"Medium Charging","Long Charging")) -> Long Charging | Q30: =IF(C30="Fast Charger",1,IF(C30="Standard Charger",2,IF(C30="Super Fast Charger",3,""))) -> 3 | R30: =TIME(HOUR(F30),MINUTE(F30),SECOND(F30)) -> 0.088194444 | S30: =DATE(YEAR(F30),MONTH(F30),DAY(F30)) -> 45064 | V30: City | W30: Avg Energy Consumption | X30: Avg Charging Duration
A31: EVS100029 | B31: Kolkata | C31: Super Fast Charger | D31: 2W EV | E31: Non-Member | F31: 22-01-2023 08:13 | G31: 22-01-2023 09:54 | H31: 101 | I31: 51.88 | J31: 12 | K31: 622.56 | L31: Credit Card | M31: 1 | N31: =IF(ev_charging_network_usage_!$I31<=10,"Low",IF(ev_charging_network_usage_!$I31<=30,"Medium","High")) -> High | O31: =IF(M31<=2,"Low Satisfaction",IF(M31<=4,"Medium Satisfaction","High Satisfaction")) -> Low Satisfaction | P31: =IF(ev_charging_network_usage_!$H31<30,"Short Charging",IF(ev_charging_network_usage_!$H31<=60,"Medium Charging","Long Charging")) -> Long Charging | Q31: =IF(C31="Fast Charger",1,IF(C31="Standard Charger",2,IF(C31="Super Fast Charger",3,""))) -> 3 | R31: =TIME(HOUR(F31),MINUTE(F31),SECOND(F31)) -> 0.34236111 | S31: =DATE(YEAR(F31),MONTH(F31),DAY(F31)) -> 44948 | V31: City Banglore | W31: =VLOOKUP(V31,$V$8:$W$14,2,FALSE) -> 30.477665 | X31: =VLOOKUP(V31,$V$8:$X$14,3,FALSE) -> 64.96066
A32: EVS100030 | B32: Delhi | C32: Super Fast Charger | D32: 2W EV | E32: Non-Member | F32: 45477.558 | G32: 45477.576 | H32: 26 | I32: 15.55 | J32: 15 | K32: 233.25 | L32: Subscription | M32: 4 | N32: =IF(ev_charging_network_usage_!$I32<=10,"Low",IF(ev_charging_network_usage_!$I32<=30,"Medium","High")) -> Medium | O32: =IF(M32<=2,"Low Satisfaction",IF(M32<=4,"Medium Satisfaction","High Satisfaction")) -> Medium Satisfaction | P32: =IF(ev_charging_network_usage_!$H32<30,"Short Charging",IF(ev_charging_network_usage_!$H32<=60,"Medium Charging","Long Charging")) -> Short Charging | Q32: =IF(C32="Fast Charger",1,IF(C32="Standard Charger",2,IF(C32="Super Fast Charger",3,""))) -> 3 | R32: =TIME(HOUR(F32),MINUTE(F32),SECOND(F32)) -> 0.55763889 | S32: =DATE(YEAR(F32),MONTH(F32),DAY(F32)) -> 45477 | V32: City Mumbai | W32: =VLOOKUP(V32,$V$8:$W$14,2,FALSE) -> 31.104659 | X32: =VLOOKUP(V32,$V$8:$X$14,3,FALSE) -> 63.280566
A33: EVS100031 | B33: Pune | C33: Super Fast Charger | D33: 4W EV | E33: Member | F33: 19-11-2023 14:46 | G33: 19-11-2023 14:56 | H33: 10 | I33: 3.08 | J33: 15 | K33: 46.2 | L33: UPI | M33: 4 | N33: =IF(ev_charging_network_usage_!$I33<=10,"Low",IF(ev_charging_network_usage_!$I33<=30,"Medium","High")) -> Low | O33: =IF(M33<=2,"Low Satisfaction",IF(M33<=4,"Medium Satisfaction","High Satisfaction")) -> Medium Satisfaction | P33: =IF(ev_charging_network_usage_!$H33<30,"Short Charging",IF(ev_charging_network_usage_!$H33<=60,"Medium Charging","Long Charging")) -> Short Charging | Q33: =IF(C33="Fast Charger",1,IF(C33="Standard Charger",2,IF(C33="Super Fast Charger",3,""))) -> 3 | R33: =TIME(HOUR(F33),MINUTE(F33),SECOND(F33)) -> 0.61527778 | S33: =DATE(YEAR(F33),MONTH(F33),DAY(F33)) -> 45249 | V33: City Delhi | W33: =VLOOKUP(V33,$V$8:$W$14,2,FALSE) -> 30.491427 | X33: =VLOOKUP(V33,$V$8:$X$14,3,FALSE) -> 64.018138
A34: EVS100032 | B34: Chennai | C34: Fast Charger | D34: 2W EV | E34: Non-Member | F34: 45298.895 | G34: 45298.925 | H34: 43 | I34: 37.55 | J34: 10 | K34: 375.5 | L34: Subscription | M34: 4 | N34: =IF(ev_charging_network_usage_!$I34<=10,"Low",IF(ev_charging_network_usage_!$I34<=30,"Medium","High")) -> High | O34: =IF(M34<=2,"Low Satisfaction",IF(M34<=4,"Medium Satisfaction","High Satisfaction")) -> Medium Satisfaction | P34: =IF(ev_charging_network_usage_!$H34<30,"Short Charging",IF(ev_charging_network_usage_!$H34<=60,"Medium Charging","Long Charging")) -> Medium Charging | Q34: =IF(C34="Fast Charger",1,IF(C34="Standard Charger",2,IF(C34="Super Fast Charger",3,""))) -> 1 | R34: =TIME(HOUR(F34),MINUTE(F34),SECOND(F34)) -> 0.89513889 | S34: =DATE(YEAR(F34),MONTH(F34),DAY(F34)) -> 45298 | V34: City Chennai | W34: =VLOOKUP(V34,$V$8:$W$14,2,FALSE) -> 30.26599 | X34: =VLOOKUP(V34,$V$8:$X$14,3,FALSE) -> 64.364882
A35: EVS100033 | B35: Mumbai | C35: Fast Charger | D35: Electric Bus | E35: Non-Member | F35: 18-02-2023 22:32 | G35: 18-02-2023 23:10 | H35: 38 | I35: 26.85 | J35: 8 | K35: 214.8 | L35: UPI | M35: 5 | N35: =IF(ev_charging_network_usage_!$I35<=10,"Low",IF(ev_charging_network_usage_!$I35<=30,"Medium","High")) -> Medium | O35: =IF(M35<=2,"Low Satisfaction",IF(M35<=4,"Medium Satisfaction","High Satisfaction")) -> High Satisfaction | P35: =IF(ev_charging_network_usage_!$H35<30,"Short Charging",IF(ev_charging_network_usage_!$H35<=60,"Medium Charging","Long Charging")) -> Medium Charging | Q35: =IF(C35="Fast Charger",1,IF(C35="Standard Charger",2,IF(C35="Super Fast Charger",3,""))) -> 1 | R35: =TIME(HOUR(F35),MINUTE(F35),SECOND(F35)) -> 0.93888889 | S35: =DATE(YEAR(F35),MONTH(F35),DAY(F35)) -> 44975 | V35: City Hyderabad | W35: =VLOOKUP(V35,$V$8:$W$14,2,FALSE) -> 31.818596 | X35: =VLOOKUP(V35,$V$8:$X$14,3,FALSE) -> 63.504843
A36: EVS100034 | B36: Mumbai | C36: Super Fast Charger | D36: Electric Bus | E36: Non-Member | F36: 45238.422 | G36: 45238.505 | H36: 119 | I36: 55.15 | J36: 15 | K36: 827.25 | L36: Credit Card | M36: 1 | N36: =IF(ev_charging_network_usage_!$I36<=10,"Low",IF(ev_charging_network_usage_!$I36<=30,"Medium","High")) -> High | O36: =IF(M36<=2,"Low Satisfaction",IF(M36<=4,"Medium Satisfaction","High Satisfaction")) -> Low Satisfaction | P36: =IF(ev_charging_network_usage_!$H36<30,"Short Charging",IF(ev_charging_network_usage_!$H36<=60,"Medium Charging","Long Charging")) -> Long Charging | Q36: =IF(C36="Fast Charger",1,IF(C36="Standard Charger",2,IF(C36="Super Fast Charger",3,""))) -> 3 | R36: =TIME(HOUR(F36),MINUTE(F36),SECOND(F36)) -> 0.42222222 | S36: =DATE(YEAR(F36),MONTH(F36),DAY(F36)) -> 45238
A37: EVS100035 | B37: Bangalore | C37: Standard Charger | D37: 4W EV | E37: Non-Member | F37: 19-08-2024 13:50 | G37: 19-08-2024 15:19 | H37: 89 | I37: 34.46 | J37: 15 | K37: 516.9 | L37: Subscription | M37: 5 | N37: =IF(ev_charging_network_usage_!$I37<=10,"Low",IF(ev_charging_network_usage_!$I37<=30,"Medium","High")) -> High | O37: =IF(M37<=2,"Low Satisfaction",IF(M37<=4,"Medium Satisfaction","High Satisfaction")) -> High Satisfaction | P37: =IF(ev_charging_network_usage_!$H37<30,"Short Charging",IF(ev_charging_network_usage_!$H37<=60,"Medium Charging","Long Charging")) -> Long Charging | Q37: =IF(C37="Fast Charger",1,IF(C37="Standard Charger",2,IF(C37="Super Fast Charger",3,""))) -> 2 | R37: =TIME(HOUR(F37),MINUTE(F37),SECOND(F37)) -> 0.57638889 | S37: =DATE(YEAR(F37),MONTH(F37),DAY(F37)) -> 45523
A38: EVS100036 | B38: Kolkata | C38: Super Fast Charger | D38: 2W EV | E38: Non-Member | F38: 31-07-2023 17:42 | G38: 31-07-2023 18:12 | H38: 30 | I38: 34.95 | J38: 8 | K38: 279.6 | L38: Wallet | M38: 4 | N38: =IF(ev_charging_network_usage_!$I38<=10,"Low",IF(ev_charging_network_usage_!$I38<=30,"Medium","High")) -> High | O38: =IF(M38<=2,"Low Satisfaction",IF(M38<=4,"Medium Satisfaction","High Satisfaction")) -> Medium Satisfaction | P38: =IF(ev_charging_network_usage_!$H38<30,"Short Charging",IF(ev_charging_network_usage_!$H38<=60,"Medium Charging","Long Charging")) -> Medium Charging | Q38: =IF(C38="Fast Charger",1,IF(C38="Standard Charger",2,IF(C38="Super Fast Charger",3,""))) -> 3 | R38: =TIME(HOUR(F38),MINUTE(F38),SECOND(F38)) -> 0.7375 | S38: =DATE(YEAR(F38),MONTH(F38),DAY(F38)) -> 45138 | U38: Q5a. | V38: what is the average energy consumed per charging session ?
A39: EVS100037 | B39: Kolkata | C39: Super Fast Charger | D39: 2W EV | E39: Member | F39: 14-05-2024 19:59 | G39: 14-05-2024 20:35 | H39: 36 | I39: 56.45 | J39: 12 | K39: 677.4 | L39: UPI | M39: 4 | N39: =IF(ev_charging_network_usage_!$I39<=10,"Low",IF(ev_charging_network_usage_!$I39<=30,"Medium","High")) -> High | O39: =IF(M39<=2,"Low Satisfaction",IF(M39<=4,"Medium Satisfaction","High Satisfaction")) -> Medium Satisfaction | P39: =IF(ev_charging_network_usage_!$H39<30,"Short Charging",IF(ev_charging_network_usage_!$H39<=60,"Medium Charging","Long Charging")) -> Medium Charging | Q39: =IF(C39="Fast Charger",1,IF(C39="Standard Charger",2,IF(C39="Super Fast Charger",3,""))) -> 3 | R39: =TIME(HOUR(F39),MINUTE(F39),SECOND(F39)) -> 0.83263889 | S39: =DATE(YEAR(F39),MONTH(F39),DAY(F39)) -> 45426 | U39: ans5a. | V39: =AVERAGE(I:I) -> 30.914457
A40: EVS100038 | B40: Pune | C40: Standard Charger | D40: 3W EV | E40: Member | F40: 23-02-2023 15:46 | G40: 23-02-2023 16:56 | H40: 70 | I40: 19.32 | J40: 15 | K40: 289.8 | L40: Wallet | M40: 5 | N40: =IF(ev_charging_network_usage_!$I40<=10,"Low",IF(ev_charging_network_usage_!$I40<=30,"Medium","High")) -> Medium | O40: =IF(M40<=2,"Low Satisfaction",IF(M40<=4,"Medium Satisfaction","High Satisfaction")) -> High Satisfaction | P40: =IF(ev_charging_network_usage_!$H40<30,"Short Charging",IF(ev_charging_network_usage_!$H40<=60,"Medium Charging","Long Charging")) -> Long Charging | Q40: =IF(C40="Fast Charger",1,IF(C40="Standard Charger",2,IF(C40="Super Fast Charger",3,""))) -> 2 | R40: =TIME(HOUR(F40),MINUTE(F40),SECOND(F40)) -> 0.65694444 | S40: =DATE(YEAR(F40),MONTH(F40),DAY(F40)) -> 44980
...

Sheet KPI
A9: TOTAL REVENUE
A10: =SUM(ev_charging_network_usage_!K:K) -> 2260491.7
A13: TOTAL CHARGING SESSIONS
A14: =COUNTA(ev_charging_network_usage_!A2:A6502) -> 6500
A16: AVERAGE ENERGY CONSUMED
A17: =AVERAGE(ev_charging_network_usage_!I:I) -> 30.914457
A19: AVERAGE CUSTOMER RATING
A20: =AVERAGE(ev_charging_network_usage_!M:M) -> 2.9927692

Sheet pivot table
C2: a) Station Utilization
C3: Count of charging sessions by Station_Type
B6: Row Labels | C6: Count of Session_ID
B7: Fast Charger | C7: 2124
B8: Standard Charger | C8: 2141
B9: Super Fast Charger | C9: 2235
B10: Grand Total | C10: 6500
C16: Average Charging Duration by Station_Type
B18: Row Labels | C18: Average of Charging_Duration_Minutes
B19: Fast Charger | C19: 64.529661
B20: Standard Charger | C20: 63.352639
B21: Super Fast Charger | C21: 64.195973
B22: Grand Total | C22: 64.027231
C26: b) Vehicle Usage
C27: Energy consumption by Vehicle_Type
B29: Row Labels | C29: Average of Energy_Consumed_kWh
B30: 2W EV | C30: 30.308164
B31: 3W EV | C31: 31.706892
B32: 4W EV | C32: 31.689943
B33: Electric Bus | C33: 29.99903
B34: Grand Total | C34: 30.914457
C42: Revenue generated by Vehicle_Type
B44: Row Labels | C44: Sum of Revenue
B45: 2W EV | C45: 562522.07
B46: 3W EV | C46: 583503.21
B47: 4W EV | C47: 560716.01
B48: Electric Bus | C48: 553750.38
B49: Grand Total | C49: 2260491.7
C53: c) Customer Experience
C54: 1.Average Rating by Station_Type
B56: Row Labels | C56: Average of Customer_Rating
B57: Fast Charger | C57: 3.0117702
B58: Standard Charger | C58: 3.0018683
B59: Super Fast Charger | C59: 2.9659955
B60: Grand Total | C60: 2.9927692
F61: Rating distribution by Membership_Type
F62: Average of Customer_Rating | G62: Column Labels
F63: Row Labels | G63: 1 | H63: 2 | I63: 3 | J63: 4 | K63: 5 | L63: Grand Total
F64: Member | G64: 1 | H64: 2 | I64: 3 | J64: 4 | K64: 5 | L64: 2.9935444
F65: Non-Member | G65: 1 | H65: 2 | I65: 3 | J65: 4 | K65: 5 | L65: 2.9919926
...

Sheet VISUALIZATION
G1: VISUALIZATION

Sheet DASSHBOARD
A38: 🔋 ELECTRONIC VEHICLE NETWORK CHARGING ANALYSIS
E50: =KPI!A10 -> 2260491.7 | I50: =KPI!A14 -> 6500 | N50: =KPI!A17 -> 30.914457 | T50: =KPI!A20 -> 2.9927692

Sheet Scatter PLot
A1: Charging_Duration_Minutes | B1: Energy_Consumed_kWh
A2: 82 | B2: 2.01
A3: 26 | B3: 25
A4: 111 | B4: 41.74
A5: 39 | B5: 33
A6: 104 | B6: 13.49
A7: 67 | B7: 52.83
A8: 23 | B8: 17.84
A9: 81 | B9: 26.42
A10: 34 | B10: 20.3
A11: 119 | B11: 3.98
A12: 35 | B12: 18.27
A13: 19 | B13: 7.58
... A6502: 55 | B6502: 46.64
